2025-02-11 17:35:37,558 - assistant_client - ERROR - Error while waiting for response: Run failed with status: failed, error: LastError(code='invalid_image_url', message='Timeout while downloading https://fileserviceuploadsperm.blob.core.windows.net/files/file-3UXStYxu3ZTU6zS2ETYJDi?se=2025-02-11T18%3A35%3A33Z&sp=r&sv=2024-08-04&sr=b&rscc=max-age%3D3599%2C%20immutable%2C%20private&rscd=attachment%3B%20filename%3Dimage.jpg&sig=PbnYRQUzraURkLZYpd7DP%2BSjiNh9rhKonJsxb/vNZUQ%3D.')
Traceback (most recent call last):
  File "/home/runner/workspace/assistant_client.py", line 214, in wait_for_response
    raise ResponseTimeoutError(error_msg)
exceptions.ResponseTimeoutError: Run failed with status: failed, error: LastError(code='invalid_image_url', message='Timeout while downloading https://fileserviceuploadsperm.blob.core.windows.net/files/file-3UXStYxu3ZTU6zS2ETYJDi?se=2025-02-11T18%3A35%3A33Z&sp=r&sv=2024-08-04&sr=b&rscc=max-age%3D3599%2C%20immutable%2C%20private&rscd=attachment%3B%20filename%3Dimage.jpg&sig=PbnYRQUzraURkLZYpd7DP%2BSjiNh9rhKonJsxb/vNZUQ%3D.')
2025-02-11 17:35:37,558 - assistant_client - ERROR - Error in process_image: Error while waiting for response: Run failed with status: failed, error: LastError(code='invalid_image_url', message='Timeout while downloading https://fileserviceuploadsperm.blob.core.windows.net/files/file-3UXStYxu3ZTU6zS2ETYJDi?se=2025-02-11T18%3A35%3A33Z&sp=r&sv=2024-08-04&sr=b&rscc=max-age%3D3599%2C%20immutable%2C%20private&rscd=attachment%3B%20filename%3Dimage.jpg&sig=PbnYRQUzraURkLZYpd7DP%2BSjiNh9rhKonJsxb/vNZUQ%3D.')
Traceback (most recent call last):
  File "/home/runner/workspace/assistant_client.py", line 214, in wait_for_response
    raise ResponseTimeoutError(error_msg)
exceptions.ResponseTimeoutError: Run failed with status: failed, error: LastError(code='invalid_image_url', message='Timeout while downloading https://fileserviceuploadsperm.blob.core.windows.net/files/file-3UXStYxu3ZTU6zS2ETYJDi?se=2025-02-11T18%3A35%3A33Z&sp=r&sv=2024-08-04&sr=b&rscc=max-age%3D3599%2C%20immutable%2C%20private&rscd=attachment%3B%20filename%3Dimage.jpg&sig=PbnYRQUzraURkLZYpd7DP%2BSjiNh9rhKonJsxb/vNZUQ%3D.')

During handling of the above exception, another exception occurred:

Traceback (most recent call last):
  File "/home/runner/workspace/assistant_client.py", line 326, in process_image
    return self.wait_for_response(thread.id, run.id, image_path)
           ^^^^^^^^^^^^^^^^^^^^^^^^^^^^^^^^^^^^^^^^^^^^^^^^^^^^^
  File "/home/runner/workspace/assistant_client.py", line 220, in wait_for_response
    raise ResponseTimeoutError(